<?xml version="1.0" encoding="utf-8"?>
<!-- This URDF was automatically created by SolidWorks to URDF Exporter! Originally created by Stephen Brawner (brawner@gmail.com) 
     Commit Version: 1.6.0-1-g15f4949  Build Version: 1.6.7594.29634
     For more information, please see http://wiki.ros.org/sw_urdf_exporter -->
<robot
  name="00-Rover_Lidar_Assembly.SLDASM">
  <link
    name="Base">
    <inertial>
      <origin
        xyz="-0.0127168728379674 -0.1980064688065 -0.0186632374341713"
        rpy="0 0 0" />
      <mass
        value="0.6393269352137" />
      <inertia
        ixx="0.00130386889495966"
        ixy="3.62307918531214E-06"
        ixz="-7.87304653654605E-07"
        iyy="0.00306827950128554"
        iyz="-2.07348461361885E-07"
        izz="0.00192485422858142" />
    </inertial>
    <visual>
      <origin
        xyz="0 0 0"
        rpy="0 0 0" />
      <geometry>
        <mesh
          filename="package://00-Rover_Lidar_Assembly.SLDASM/meshes/Base.STL" />
      </geometry>
      <material
        name="">
        <color
          rgba="0.250980392156863 0.250980392156863 0.250980392156863 1" />
      </material>
    </visual>
    <collision>
      <origin
        xyz="0 0 0"
        rpy="0 0 0" />
      <geometry>
        <mesh
          filename="package://00-Rover_Lidar_Assembly.SLDASM/meshes/Base.STL" />
      </geometry>
    </collision>
  </link>
  <link
    name="Wheel_FR">
    <inertial>
      <origin
        xyz="0.00379939380568042 1.50990955849473E-10 -1.40165351547594E-10"
        rpy="0 0 0" />
      <mass
        value="0.47503084788529" />
      <inertia
        ixx="0.000871741191702141"
        ixy="1.01417054886553E-12"
        ixz="5.97464463751377E-13"
        iyy="0.000581978720417614"
        iyz="4.78811274716114E-12"
        izz="0.000581979311396503" />
    </inertial>
    <visual>
      <origin
        xyz="0 0 0"
        rpy="0 0 0" />
      <geometry>
        <mesh
          filename="package://00-Rover_Lidar_Assembly.SLDASM/meshes/Wheel_FR.STL" />
      </geometry>
      <material
        name="">
        <color
          rgba="0.250980392156863 0.250980392156863 0.250980392156863 1" />
      </material>
    </visual>
    <collision>
      <origin
        xyz="0 0 0"
        rpy="0 0 0" />
      <geometry>
        <mesh
          filename="package://00-Rover_Lidar_Assembly.SLDASM/meshes/Wheel_FR.STL" />
      </geometry>
    </collision>
  </link>
  <joint
    name="Wheel_FR"
    type="continuous">
    <origin
      xyz="0.086547 -0.182 -0.15755"
      rpy="1.5708 1.5708 0" />
    <parent
      link="Base" />
    <child
      link="Wheel_FR" />
    <axis
      xyz="1 0 0" />
    <limit
      lower="0"
      upper="0"
      effort="0"
      velocity="0" />
  </joint>
  <link
    name="Wheel_FL">
    <inertial>
      <origin
        xyz="0.00379939380568045 1.50991039116199E-10 -1.40165240525292E-10"
        rpy="0 0 0" />
      <mass
        value="0.47503084788529" />
      <inertia
        ixx="0.000871741191702147"
        ixy="1.01416940224523E-12"
        ixz="5.97464669068177E-13"
        iyy="0.000581978720417615"
        iyz="4.78811406782948E-12"
        izz="0.000581979311396506" />
    </inertial>
    <visual>
      <origin
        xyz="0 0 0"
        rpy="0 0 0" />
      <geometry>
        <mesh
          filename="package://00-Rover_Lidar_Assembly.SLDASM/meshes/Wheel_FL.STL" />
      </geometry>
      <material
        name="">
        <color
          rgba="0.250980392156863 0.250980392156863 0.250980392156863 1" />
      </material>
    </visual>
    <collision>
      <origin
        xyz="0 0 0"
        rpy="0 0 0" />
      <geometry>
        <mesh
          filename="package://00-Rover_Lidar_Assembly.SLDASM/meshes/Wheel_FL.STL" />
      </geometry>
    </collision>
  </link>
  <joint
    name="Wheel_FL"
    type="continuous">
    <origin
      xyz="0.086547 -0.182 0.12045"
      rpy="1.5708 -1.5708 0" />
    <parent
      link="Base" />
    <child
      link="Wheel_FL" />
    <axis
      xyz="1 0 0" />
    <limit
      lower="0"
      upper="0"
      effort="0"
      velocity="0" />
  </joint>
  <link
    name="Wheel_BR">
    <inertial>
      <origin
        xyz="0.00379939380568037 1.50990955849473E-10 -1.40165656858926E-10"
        rpy="0 0 0" />
      <mass
        value="0.475030847885291" />
      <inertia
        ixx="0.000871741191702142"
        ixy="1.0141687068998E-12"
        ixz="5.974658575447E-13"
        iyy="0.000581978720417615"
        iyz="4.78811001961573E-12"
        izz="0.000581979311396504" />
    </inertial>
    <visual>
      <origin
        xyz="0 0 0"
        rpy="0 0 0" />
      <geometry>
        <mesh
          filename="package://00-Rover_Lidar_Assembly.SLDASM/meshes/Wheel_BR.STL" />
      </geometry>
      <material
        name="">
        <color
          rgba="0.250980392156863 0.250980392156863 0.250980392156863 1" />
      </material>
    </visual>
    <collision>
      <origin
        xyz="0 0 0"
        rpy="0 0 0" />
      <geometry>
        <mesh
          filename="package://00-Rover_Lidar_Assembly.SLDASM/meshes/Wheel_BR.STL" />
      </geometry>
    </collision>
  </link>
  <joint
    name="Wheel_BR"
    type="continuous">
    <origin
      xyz="-0.10845 -0.182 -0.15755"
      rpy="1.5708 1.5708 0" />
    <parent
      link="Base" />
    <child
      link="Wheel_BR" />
    <axis
      xyz="1 0 0" />
    <limit
      lower="0"
      upper="0"
      effort="0"
      velocity="0" />
  </joint>
  <link
    name="Wheel_BL">
    <inertial>
      <origin
        xyz="0.00379939380568042 1.50991052993987E-10 -1.40165240525292E-10"
        rpy="0 0 0" />
      <mass
        value="0.47503084788529" />
      <inertia
        ixx="0.000871741191702149"
        ixy="1.01416993028101E-12"
        ixz="5.97463617204028E-13"
        iyy="0.000581978720417616"
        iyz="4.78811353399934E-12"
        izz="0.000581979311396506" />
    </inertial>
    <visual>
      <origin
        xyz="0 0 0"
        rpy="0 0 0" />
      <geometry>
        <mesh
          filename="package://00-Rover_Lidar_Assembly.SLDASM/meshes/Wheel_BL.STL" />
      </geometry>
      <material
        name="">
        <color
          rgba="0.250980392156863 0.250980392156863 0.250980392156863 1" />
      </material>
    </visual>
    <collision>
      <origin
        xyz="0 0 0"
        rpy="0 0 0" />
      <geometry>
        <mesh
          filename="package://00-Rover_Lidar_Assembly.SLDASM/meshes/Wheel_BL.STL" />
      </geometry>
    </collision>
  </link>
  <joint
    name="Wheel_BL"
    type="continuous">
    <origin
      xyz="-0.10845 -0.182 0.12045"
      rpy="1.5708 -1.5708 0" />
    <parent
      link="Base" />
    <child
      link="Wheel_BL" />
    <axis
      xyz="1 0 0" />
    <limit
      lower="0"
      upper="0"
      effort="0"
      velocity="0" />
  </joint>
</robot>